Workbook
Name Lookup_Table: 'Analysis - 1'!$R$4:$X$8
Name Slicer_Country: #N/A
Name Slicer_Month_Name: #N/A
Name Slicer_Year: #N/A

Sheet Analysis - 1
A4: #Transaction | B4: COGS | C4: Total Revenue | D4: Total Profit | E4: OrderQuantity | F4: All Products | G4: Sold Products | H4: Unsold Products | I4: % Profit Margin | M4: Year | N4: Revenue | O4: Total Profit | P4: #Transaction | R4: Row Labels | S4: #Transaction | T4: COGS | U4: Total Revenue | V4: Total Profit | W4: OrderQuantity | X4: % Profit Margin
A5: 60398 | B5: 1.8080237e+08 | C5: 3.0709295e+08 | D5: 1.2629058e+08 | E5: 60398 | F5: 606 | G5: 158 | H5: 448 | I5: 0.41124545 | M5: 2005 | N5: 33370192 | O5: 13403627 | P5: 1013 | R5: 2005 | S5: 1013 | T5: 19966566 | U5: 33370192 | V5: 13403627 | W5: 1013 | X5: 0.40166465
M6: 2006 | N6: 69484523 | O6: 28177776 | P6: 2677 | R6: 2006 | S6: 2677 | T6: 41306747 | U6: 69484523 | V6: 28177776 | W6: 2677 | X6: 0.40552594
M7: 2007 | N7: 1.0237961e+08 | O7: 42547111 | P7: 24443 | R7: 2007 | S7: 24443 | T7: 59832502 | U7: 1.0237961e+08 | V7: 42547111 | W7: 24443 | X7: 0.41558187
M8: 2008 | N8: 1.0185862e+08 | O8: 42162064 | P8: 32265 | R8: 2008 | S8: 32265 | T8: 59696553 | U8: 1.0185862e+08 | V8: 42162064 | W8: 32265 | X8: 0.41392732
B9: Year | C9: Revenue | D9: Total Profit | E9: #Transaction
B10: 2005 | C10: 33370192 | D10: 13403627 | E10: 1013 | P10: Year
B11: 2006 | C11: 69484523 | D11: 28177776 | E11: 2677 | M11: Check Selected Year | N11: 1 | P11: 2005
B12: 2007 | C12: 1.0237961e+08 | D12: 42547111 | E12: 24443 | P12: 2006
B13: 2008 | C13: 1.0185862e+08 | D13: 42162064 | E13: 32265 | P13: 2007
P14: 2008
C15: option button | D15: 2 | M15: Total Profit | N15: Year | O15: Profit | R15: Total COGS | S15: Year | T15: COGS | U15: Percentage | W15: % Profit Margin | X15: Year | Y15: Profit Margin | Z15: Percentage
M16: Selected Year | N16: =IF(N11=1,P11,0) -> 2005 | O16: =IFERROR(VLOOKUP('Analysis - 1'!N16,Lookup_Table,5,0),0) -> 13403627 | P16: =IFERROR($O16/SUM($O$16:$O$17),0) -> 1 | R16: Selected Year | S16: =IF(N11=1,P11,0) -> 2005 | T16: =IFERROR(VLOOKUP('Analysis - 1'!S16,Lookup_Table,3,0),0) -> 19966566 | U16: =IFERROR($T16/SUM($T$16:$T$17),0) -> 1 | W16: Selected Year | X16: =IF(N11=1,P11,0) -> 2005 | Y16: =IFERROR(VLOOKUP('Analysis - 1'!X16,Lookup_Table,7,0),0) -> 0.40166465 | Z16: =IFERROR($Y16/SUM($Y$16:$Y$17),0) -> 1
B17: Year | C17: {=_xlfn.IFS($D$15=1,C9,$D$15=2,D9,$D$15=3,E9)} -> Total Profit | D17: ="Average"&" "& C17 -> Average Total Profit | E17: Aboce Average | M17: Previous Year | N17: =$P$11-1 -> 2004 | O17: =IFERROR(VLOOKUP('Analysis - 1'!N17,Lookup_Table,5,0),0) -> 0 | P17: =IFERROR($O17/SUM($O$16:$O$17),0) -> 0 | R17: Previous Year | S17: =$P$11-1 -> 2004 | T17: =IFERROR(VLOOKUP('Analysis - 1'!S17,Lookup_Table,3,0),0) -> 0 | U17: =IFERROR($T17/SUM($T$16:$T$17),0) -> 0 | W17: Previous Year | X17: =$P$11-1 -> 2004 | Y17: =IFERROR(VLOOKUP('Analysis - 1'!X17,Lookup_Table,7,0),0) -> 0 | Z17: =IFERROR($Y17/SUM($Y$16:$Y$17),0) -> 0
B18: 2005 | C18: {=_xlfn.IFS($D$15=1,C10,$D$15=2,D10,$D$15=3,E10)} -> 13403627 | D18: =AVERAGE($C$18:$C$21) -> 31572644 | E18: =IF(C18>D18,C18,"")
B19: 2006 | C19: {=_xlfn.IFS($D$15=1,C11,$D$15=2,D11,$D$15=3,E11)} -> 28177776 | D19: =AVERAGE($C$18:$C$21) -> 31572644 | E19: =IF(C19>D19,C19,"") | M19: YoY Change | N19: =P16-P17 -> 1 | R19: YoY Change | S19: =U16-U17 -> 1 | W19: YoY Change | X19: =Z16-Z17 -> 1
B20: 2007 | C20: {=_xlfn.IFS($D$15=1,C12,$D$15=2,D12,$D$15=3,E12)} -> 42547111 | D20: =AVERAGE($C$18:$C$21) -> 31572644 | E20: =IF(C20>D20,C20,"") -> 42547111
B21: 2008 | C21: {=_xlfn.IFS($D$15=1,C13,$D$15=2,D13,$D$15=3,E13)} -> 42162064 | D21: =AVERAGE($C$18:$C$21) -> 31572644 | E21: =IF(C21>D21,C21,"") -> 42162064 | M21: Total Revenue | N21: Year | O21: Revenue | P21: Percentage | R21: Total Quantity | S21: Year | T21: QTY | U21: Percentage | W21: Transaction | X21: Year | Y21: Transaction | Z21: Percentage
M22: Selected Year | N22: =IF(N11=1,P11,0) -> 2005 | O22: =IFERROR(VLOOKUP('Analysis - 1'!N22,Lookup_Table,4,0),0) -> 33370192 | P22: =IFERROR($O22/SUM($O$22:$O$23),0) -> 1 | R22: Selected Year | S22: =IF(N11=1,P11,0) -> 2005 | T22: =IFERROR(VLOOKUP('Analysis - 1'!S22,Lookup_Table,6,0),0) -> 1013 | U22: =IFERROR($T22/SUM($T$22:$T$23),0) -> 1 | W22: Selected Year | X22: =IF(N11=1,P11,0) -> 2005 | Y22: =IFERROR(VLOOKUP('Analysis - 1'!X22,Lookup_Table,2,0),0) -> 1013 | Z22: =IFERROR($Y22/SUM($Y$22:$Y$23),0) -> 1
M23: Previous Year | N23: =$P$11-1 -> 2004 | O23: =IFERROR(VLOOKUP('Analysis - 1'!N23,Lookup_Table,4,0),0) -> 0 | P23: =IFERROR($O23/SUM($O$22:$O$23),0) -> 0 | R23: Previous Year | S23: =$P$11-1 -> 2004 | T23: =IFERROR(VLOOKUP('Analysis - 1'!S23,Lookup_Table,6,0),0) -> 0 | U23: =IFERROR($T23/SUM($T$22:$T$23),0) -> 0 | W23: Previous Year | X23: =$P$11-1 -> 2004 | Y23: =IFERROR(VLOOKUP('Analysis - 1'!X23,Lookup_Table,2,0),0) -> 0 | Z23: =IFERROR($Y23/SUM($Y$22:$Y$23),0) -> 0
B24: Above Average | D24: Caption
A25: Total | B25: =SUM(E18:E21) -> 84709175 | D25: ="of" &" "& C17 &" "&"comes from the highlighted years" -> of Total Profit comes from the highlighted years | M25: YoY Change | N25: =P22-P23 -> 1 | R25: YoY Change | S25: =U22-U23 -> 1 | W25: YoY Change | X25: =Z22-Z23 -> 1
A26: Percentage | B26: =B25/SUM(C18:C21) -> 0.67074818

Sheet Analysis - 2
B4: Month Name | C4: Total Profit
B5: Jan | C5: 10223846 | J5: 1 | K5: =LARGE($C$5:$C$16,J5) -> 13733395 | L5: =INDEX($B$5:$B$16,MATCH($K5,C5:C16,0)) -> May
B6: Feb | C6: 10792830 | J6: 2 | K6: =LARGE($C$5:$C$16,J6) -> 13445658 | L6: =INDEX($B$5:$B$16,MATCH($K6,C6:C17,0)) -> May
B7: Mar | C7: 11283963 | J7: 3 | K7: =LARGE($C$5:$C$16,J7) -> 13143417 | L7: =INDEX($B$5:$B$16,MATCH($K7,C7:C18,0)) -> Oct
B8: Apr | C8: 11839838
B9: May | C9: 13733395 | K9: =SUM(K5:K7)/SUM(C5:C16) -> 0.31928329
B10: Jun | C10: 13445658
B11: Jul | C11: 8108100.7 | K11: ="In"&" "&'Analysis - 1'!P11 -> In 2005
B12: Aug | C12: 8035078.6
B13: Sep | C13: 8046581.2
B14: Oct | C14: 8675444.4
B15: Nov | C15: 8962424.9
B16: Dec | C16: 13143417
B21: Day Name | C21: Total Profit | E21: =B21 -> Day Name | F21: =C21 -> Total Profit | G21: Highlights
B22: Mon | C22: 17943295 | E22: =B22 -> Mon | F22: =C22 -> 17943295 | G22: {=IFERROR(_xlfn.IFS(F22=$C$31,F22,F22=$C$32,F22,F22=$C$33,F22)," ")}
B23: Tue | C23: 17685313 | E23: =B23 -> Tue | F23: =C23 -> 17685313 | G23: {=IFERROR(_xlfn.IFS(F23=$C$31,F23,F23=$C$32,F23,F23=$C$33,F23)," ")}
B24: Wed | C24: 18218770 | E24: =B24 -> Wed | F24: =C24 -> 18218770 | G24: {=IFERROR(_xlfn.IFS(F24=$C$31,F24,F24=$C$32,F24,F24=$C$33,F24)," ")} -> 18218770
B25: Thu | C25: 18810562 | E25: =B25 -> Thu | F25: =C25 -> 18810562 | G25: {=IFERROR(_xlfn.IFS(F25=$C$31,F25,F25=$C$32,F25,F25=$C$33,F25)," ")} -> 18810562
B26: Fri | C26: 18279688 | E26: =B26 -> Fri | F26: =C26 -> 18279688 | G26: {=IFERROR(_xlfn.IFS(F26=$C$31,F26,F26=$C$32,F26,F26=$C$33,F26)," ")} -> 18279688
B27: Sat | C27: 17729640 | E27: =B27 -> Sat | F27: =C27 -> 17729640 | G27: {=IFERROR(_xlfn.IFS(F27=$C$31,F27,F27=$C$32,F27,F27=$C$33,F27)," ")}
B28: Sun | C28: 17623310 | E28: =B28 -> Sun | F28: =C28 -> 17623310 | G28: {=IFERROR(_xlfn.IFS(F28=$C$31,F28,F28=$C$32,F28,F28=$C$33,F28)," ")}
B31: 1 | C31: =LARGE($F$22:$F$28,B31) -> 18810562 | F31: =SUM(G22:G28)/SUM(F22:F28) -> 0.43795048
B32: 2 | C32: =LARGE($F$22:$F$28,B32) -> 18279688
B33: 3 | C33: =LARGE($F$22:$F$28,B33) -> 18218770
B41: Week Types | C41: Total Profit | D41: %
B42: Weekday | C42: 90937627 | D42: =C42/SUM(C42:C43) -> 0.7200666
B43: Weekend | C43: 35352950 | D43: =C43/SUM($C$42:$C$43) -> 0.2799334
B45: Top
B46: =MAX(D42:D43) -> 0.7200666
B47: =INDEX(B42:B43,MATCH(B46,D42:D43,0))&" "&"Make up" -> Weekday Make up
B59: Quarter | C59: Total Profit | D59: Sum of Total Profit
B60: Q1 | C60: 32300639 | D60: 0.25576444
B61: Q2 | C61: 39018891 | D61: 0.30896122
B62: Q3 | C62: 24189761 | D62: 0.1915405
B63: Q4 | C63: 30781287 | D63: 0.24373383

Sheet Products & Customers Analysis
H2: Products | I2: Profit | J2: Percentage
B3: Month Name | C3: Total Profit | E3: =B3 -> Month Name | F3: =C3 -> Total Profit | H3: Top - 5 | I3: =SUM(F4:F8) -> 31270388 | J3: =I3/SUM($I$3:$I$4) -> 0.55906791
B4: Mountain-200 Black, 46 | C4: 6607699.9 | E4: =B4 -> Mountain-200 Black, 46 | F4: =C4 -> 6607699.9 | H4: Others | I4: =SUM(F5:F9) -> 24662688 | J4: =I4/SUM($I$3:$I$4) -> 0.44093209 | R4: All Products | S4: Sold Products | T4: Unsold Products | Z4: #Customers | AA4: Average Customer Age
B5: Mountain-200 Black, 42 | C5: 6413590.1 | E5: =B5 -> Mountain-200 Black, 42 | F5: =C5 -> 6413590.1 | R5: 606 | S5: 158 | T5: 448 | Z5: 18484 | AA5: 45.595975
B6: Mountain-200 Silver, 46 | C6: 6142629.2 | E6: =B6 -> Mountain-200 Silver, 46 | F6: =C6 -> 6142629.2
B7: Mountain-200 Black, 38 | C7: 6071041.4 | E7: =B7 -> Mountain-200 Black, 38 | F7: =C7 -> 6071041.4
B8: Mountain-200 Silver, 42 | C8: 6035426.9 | E8: =B8 -> Mountain-200 Silver, 42 | F8: =C8 -> 6035426.9 | R8: Color | S8: Sum of Total Profit | U8: =R8 -> Color | V8: =S8 -> Sum of Total Profit | W8: Highlight | Z8: Gender | AA8: Sum of Total Profit
B9: Mountain-200 Silver, 38 | C9: 6033397.2 | R9: Black | S9: 39160817 | U9: =R9 -> Black | V9: =S9 -> 39160817 | W9: =V9 -> 39160817 | Z9: F | AA9: 63636815
B10: Road-150 Red, 62 | C10: 5022903.6 | E10: Others | R10: Red | S10: 31594382 | U10: =R10 -> Red | V10: =S10 -> 31594382 | W10: =V10 -> 31594382 | Z10: M | AA10: 62653763
B11: Road-150 Red, 48 | C11: 4638799.2 | E11: =B9 -> Mountain-200 Silver, 38 | F11: =C9 -> 6033397.2 | R11: Silver | S11: 23916414 | U11: =R11 -> Silver | V11: =S11 -> 23916414 | W11: =V11 -> 23916414
B12: Road-150 Red, 52 | C12: 4558601.6 | E12: =B10 -> Road-150 Red, 62 | F12: =C10 -> 5022903.6 | R12: Yellow | S12: 19035074 | U12: =R12 -> Yellow | V12: =S12 -> 19035074
B13: Road-150 Red, 56 | C13: 4399613.3 | E13: =B11 -> Road-150 Red, 48 | F13: =C11 -> 4638799.2 | R13: Blue | S13: 9425341 | U13: =R13 -> Blue | V13: =S13 -> 9425341 | Z13: =Z8 -> Gender | AA13: =AA8 -> Sum of Total Profit | AB13: percentage
B14: Road-150 Red, 44 | C14: 4154799.5 | E14: =B12 -> Road-150 Red, 52 | F14: =C12 -> 4558601.6 | R14: Unspecified | S14: 2864789.6 | U14: =R14 -> Unspecified | V14: =S14 -> 2864789.6 | Z14: =Z9 -> F | AA14: =AA9/SUM(AA9:AA10) -> 0.50389202 | AB14: 1
B15: Road-250 Black, 52 | C15: 2931267.1 | E15: =B13 -> Road-150 Red, 56 | F15: =C13 -> 4399613.3 | R15: Multi | S15: 260179.77 | U15: =R15 -> Multi | V15: =S15 -> 260179.77 | Z15: =Z10 -> M | AA15: =AA10/SUM(AA9:AA10) -> 0.49610798 | AB15: 1
B16: Road-250 Red, 58 | C16: 2837717.3 | E16: =B14 -> Road-150 Red, 44 | F16: =C14 -> 4154799.5 | R16: White | S16: 33580.486 | U16: =R16 -> White | V16: =S16 -> 33580.486
B17: Road-250 Black, 48 | C17: 2622907.4 | E17: =B15 -> Road-250 Black, 52 | F17: =C15 -> 2931267.1 | R17: Grey | S17: 0
B18: Road-250 Black, 58 | C18: 2535296.6 | E18: =B16 -> Road-250 Red, 58 | F18: =C16 -> 2837717.3 | R18: Silver/Black | S18: 0
B19: Road-250 Black, 44 | C19: 2442271.2 | E19: =B17 -> Road-250 Black, 48 | F19: =C17 -> 2622907.4
B20: Touring-1000 Blue, 46 | C20: 1752842.7 | E20: =B18 -> Road-250 Black, 58 | F20: =C18 -> 2535296.6
B21: Road-350-W Yellow, 40 | C21: 1621654.6 | E21: =B19 -> Road-250 Black, 44 | F21: =C19 -> 2442271.2
B22: Touring-1000 Yellow, 46 | C22: 1589556.8 | E22: =B20 -> Touring-1000 Blue, 46 | F22: =C20 -> 1752842.7
B23: Road-350-W Yellow, 42 | C23: 1569083.8 | E23: =B21 -> Road-350-W Yellow, 40 | F23: =C21 -> 1621654.6
B24: Road-350-W Yellow, 48 | C24: 1564754.4 | E24: =B22 -> Touring-1000 Yellow, 46 | F24: =C22 -> 1589556.8 | Z24: Age Group | AA24: Total Profit | AD24: =Z24 -> Age Group | AE24: =AA24 -> Total Profit | AF24: Highlights
B25: Touring-1000 Blue, 54 | C25: 1554373.6 | E25: =B23 -> Road-350-W Yellow, 42 | F25: =C23 -> 1569083.8 | Z25: 30 - 34 | AA25: 14868804 | AD25: =Z25 -> 30 - 34 | AE25: =AA25 -> 14868804
B26: Touring-1000 Yellow, 54 | C26: 1551667.2 | E26: =B24 -> Road-350-W Yellow, 48 | F26: =C24 -> 1564754.4 | Z26: 35 - 39 | AA26: 16786359 | AD26: =Z26 -> 35 - 39 | AE26: =AA26 -> 16786359
B27: Road-250 Red, 48 | C27: 1528303.6 | E27: =B25 -> Touring-1000 Blue, 54 | F27: =C25 -> 1554373.6 | Z27: 40 - 44 | AA27: 15801507 | AD27: =Z27 -> 40 - 44 | AE27: =AA27 -> 15801507
B28: Touring-1000 Yellow, 50 | C28: 1489420.1 | E28: =B26 -> Touring-1000 Yellow, 54 | F28: =C26 -> 1551667.2 | Z28: 45 - 49 | AA28: 15143376 | AD28: =Z28 -> 45 - 49 | AE28: =AA28 -> 15143376
B29: Road-350-W Yellow, 44 | C29: 1424977.9 | E29: =B27 -> Road-250 Red, 48 | F29: =C27 -> 1528303.6 | Z29: 50 plus | AA29: 63690532 | AD29: =Z29 -> 50 plus | AE29: =AA29 -> 63690532 | AF29: =AE29 -> 63690532
B30: Touring-1000 Blue, 50 | C30: 1419955.9 | E30: =B28 -> Touring-1000 Yellow, 50 | F30: =C28 -> 1489420.1
B31: Touring-1000 Blue, 60 | C31: 1389283.4 | E31: =B29 -> Road-350-W Yellow, 44 | F31: =C29 -> 1424977.9
B32: Touring-1000 Yellow, 60 | C32: 1381164.2 | E32: =B30 -> Touring-1000 Blue, 50 | F32: =C30 -> 1419955.9
B33: Road-250 Red, 44 | C33: 1357259.4 | E33: =B31 -> Touring-1000 Blue, 60 | F33: =C31 -> 1389283.4
B34: Road-250 Red, 52 | C34: 1270350.4 | E34: =B32 -> Touring-1000 Yellow, 60 | F34: =C32 -> 1381164.2
B35: Road-550-W Yellow, 42 | C35: 1223209.6 | E35: =B33 -> Road-250 Red, 44 | F35: =C33 -> 1357259.4
B36: Road-550-W Yellow, 44 | C36: 1214653.3 | E36: =B34 -> Road-250 Red, 52 | F36: =C34 -> 1270350.4
B37: Road-550-W Yellow, 48 | C37: 1186046.2 | E37: =B35 -> Road-550-W Yellow, 42 | F37: =C35 -> 1223209.6
B38: Road-550-W Yellow, 38 | C38: 1122748.3 | E38: =B36 -> Road-550-W Yellow, 44 | F38: =C36 -> 1214653.3
B39: Road-550-W Yellow, 40 | C39: 1089403.7 | E39: =B37 -> Road-550-W Yellow, 48 | F39: =C37 -> 1186046.2 | H39: Product price type | I39: Sum of Total Profit | R39: Full Name | S39: Sum of Total Profit | U39: =R39 -> Full Name | V39: =S39 -> Sum of Total Profit | W39: Duplicate
B40: Mountain-100 Black, 44 | C40: 977704.89 | E40: =B38 -> Road-550-W Yellow, 38 | F40: =C38 -> 1122748.3 | H40: Expensive | I40: 1.2052131e+08 | R40: Willie Xu | S40: 80609.041 | U40: =R40 -> Willie Xu | V40: =S40 -> 80609.041 | W40: 434.7409
B41: Mountain-100 Black, 48 | C41: 976227.99 | E41: =B39 -> Road-550-W Yellow, 40 | F41: =C39 -> 1089403.7 | H41: Less Expensive | I41: 5769264.5 | R41: Jordan Turner | S41: 78346.273 | U41: =R41 -> Jordan Turner | V41: =S41 -> 78346.273 | W41: 306.6959
...

Sheet Time Series Dashboard

Sheet Details Dashboard
